WARNING:werkzeug: * Debugger is active!
INFO:werkzeug: * Debugger PIN: 608-645-688
INFO:werkzeug:127.0.0.1 - - [22/Apr/2025 16:38:13] "GET /register HTTP/1.1" 200 -
INFO:werkzeug:127.0.0.1 - - [22/Apr/2025 16:38:14] "GET /static/js/scripts.js HTTP/1.1" 304 -
INFO:werkzeug:127.0.0.1 - - [22/Apr/2025 16:38:14] "GET /static/css/custom.css HTTP/1.1" 304 -
INFO:werkzeug:127.0.0.1 - - [22/Apr/2025 16:38:15] "GET /register HTTP/1.1" 200 -
INFO:werkzeug:127.0.0.1 - - [22/Apr/2025 16:38:15] "GET /static/css/custom.css HTTP/1.1" 304 -
INFO:werkzeug:127.0.0.1 - - [22/Apr/2025 16:38:16] "GET /static/js/scripts.js HTTP/1.1" 304 -
INFO:werkzeug:127.0.0.1 - - [22/Apr/2025 16:38:34] "POST /register HTTP/1.1" 500 -
Traceback (most recent call last):
  File "C:\Users\HAJAR\AppData\Local\Programs\Python\Python313\Lib\site-packages\wtforms\validators.py", line 401, in __call__
    import email_validator
ModuleNotFoundError: No module named 'email_validator'

The above exception was the direct cause of the following exception:

Traceback (most recent call last):
  File "C:\Users\HAJAR\AppData\Local\Programs\Python\Python313\Lib\site-packages\flask\app.py", line 1536, in __call__
    return self.wsgi_app(environ, start_response)
           ~~~~~~~~~~~~~^^^^^^^^^^^^^^^^^^^^^^^^^
  File "C:\Users\HAJAR\AppData\Local\Programs\Python\Python313\Lib\site-packages\werkzeug\middleware\proxy_fix.py", line 183, in __call__
    return self.app(environ, start_response)
           ~~~~~~~~^^^^^^^^^^^^^^^^^^^^^^^^^
  File "C:\Users\HAJAR\AppData\Local\Programs\Python\Python313\Lib\site-packages\flask\app.py", line 1514, in wsgi_app
    response = self.handle_exception(e)
  File "C:\Users\HAJAR\AppData\Local\Programs\Python\Python313\Lib\site-packages\flask\app.py", line 1511, in wsgi_app
    response = self.full_dispatch_request()
  File "C:\Users\HAJAR\AppData\Local\Programs\Python\Python313\Lib\site-packages\flask\app.py", line 919, in full_dispatch_request
    rv = self.handle_user_exception(e)
  File "C:\Users\HAJAR\AppData\Local\Programs\Python\Python313\Lib\site-packages\flask\app.py", line 917, in full_dispatch_request
    rv = self.dispatch_request()
  File "C:\Users\HAJAR\AppData\Local\Programs\Python\Python313\Lib\site-packages\flask\app.py", line 902, in dispatch_request
    return self.ensure_sync(self.view_functions[rule.endpoint])(**view_args)  # type: ignore[no-any-return]
           ~~~~~~~~~~~~~~~~~~~~~~~~~~~~~~~~~~~~~~~~~~~~~~~~~~~~^^^^^^^^^^^^^
  File "C:\Users\HAJAR\Downloads\student-portfolio-source\routes.py", line 40, in register
    if form.validate_on_submit():
       ~~~~~~~~~~~~~~~~~~~~~~~^^
  File "C:\Users\HAJAR\AppData\Local\Programs\Python\Python313\Lib\site-packages\flask_wtf\form.py", line 86, in validate_on_submit
    return self.is_submitted() and self.validate(extra_validators=extra_validators)
                                   ~~~~~~~~~~~~~^^^^^^^^^^^^^^^^^^^^^^^^^^^^^^^^^^^
  File "C:\Users\HAJAR\AppData\Local\Programs\Python\Python313\Lib\site-packages\wtforms\form.py", line 330, in validate
    return super().validate(extra)
           ~~~~~~~~~~~~~~~~^^^^^^^
  File "C:\Users\HAJAR\AppData\Local\Programs\Python\Python313\Lib\site-packages\wtforms\form.py", line 147, in validate
    if not field.validate(self, extra):
           ~~~~~~~~~~~~~~^^^^^^^^^^^^^
  File "C:\Users\HAJAR\AppData\Local\Programs\Python\Python313\Lib\site-packages\wtforms\fields\core.py", line 234, in validate
    stop_validation = self._run_validation_chain(form, chain)
  File "C:\Users\HAJAR\AppData\Local\Programs\Python\Python313\Lib\site-packages\wtforms\fields\core.py", line 254, in _run_validation_chain
    validator(form, self)
    ~~~~~~~~~^^^^^^^^^^^^
  File "C:\Users\HAJAR\AppData\Local\Programs\Python\Python313\Lib\site-packages\wtforms\validators.py", line 403, in __call__
    raise Exception(
    ^^^^^^^^^^
Exception: Install 'email_validator' for email validation support.
INFO:werkzeug:127.0.0.1 - - [22/Apr/2025 16:38:34] "GET /register?__debugger__=yes&cmd=resource&f=style.css HTTP/1.1" 304 -
INFO:werkzeug:127.0.0.1 - - [22/Apr/2025 16:38:34] "GET /register?__debugger__=yes&cmd=resource&f=debugger.js HTTP/1.1" 304 -
INFO:werkzeug:127.0.0.1 - - [22/Apr/2025 16:38:34] "GET /register?__debugger__=yes&cmd=resource&f=console.png&s=ZE6QS26MonfmzHEm7qqx HTTP/1.1" 200 -
INFO:werkzeug:127.0.0.1 - - [22/Apr/2025 16:38:34] "GET /register?__debugger__=yes&cmd=resource&f=console.png HTTP/1.1" 304 -
INFO:werkzeug:127.0.0.1 - - [22/Apr/2025 16:38:45] "POST /register HTTP/1.1" 500 -
Traceback (most recent call last):
  File "C:\Users\HAJAR\AppData\Local\Programs\Python\Python313\Lib\site-packages\wtforms\validators.py", line 401, in __call__
    import email_validator
ModuleNotFoundError: No module named 'email_validator'

The above exception was the direct cause of the following exception:

Traceback (most recent call last):
  File "C:\Users\HAJAR\AppData\Local\Programs\Python\Python313\Lib\site-packages\flask\app.py", line 1536, in __call__
    return self.wsgi_app(environ, start_response)
           ~~~~~~~~~~~~~^^^^^^^^^^^^^^^^^^^^^^^^^
  File "C:\Users\HAJAR\AppData\Local\Programs\Python\Python313\Lib\site-packages\werkzeug\middleware\proxy_fix.py", line 183, in __call__
    return self.app(environ, start_response)
           ~~~~~~~~^^^^^^^^^^^^^^^^^^^^^^^^^
  File "C:\Users\HAJAR\AppData\Local\Programs\Python\Python313\Lib\site-packages\flask\app.py", line 1514, in wsgi_app
    response = self.handle_exception(e)
  File "C:\Users\HAJAR\AppData\Local\Programs\Python\Python313\Lib\site-packages\flask\app.py", line 1511, in wsgi_app
    response = self.full_dispatch_request()
  File "C:\Users\HAJAR\AppData\Local\Programs\Python\Python313\Lib\site-packages\flask\app.py", line 919, in full_dispatch_request
    rv = self.handle_user_exception(e)
  File "C:\Users\HAJAR\AppData\Local\Programs\Python\Python313\Lib\site-packages\flask\app.py", line 917, in full_dispatch_request
    rv = self.dispatch_request()
  File "C:\Users\HAJAR\AppData\Local\Programs\Python\Python313\Lib\site-packages\flask\app.py", line 902, in dispatch_request
    return self.ensure_sync(self.view_functions[rule.endpoint])(**view_args)  # type: ignore[no-any-return]
           ~~~~~~~~~~~~~~~~~~~~~~~~~~~~~~~~~~~~~~~~~~~~~~~~~~~~^^^^^^^^^^^^^
  File "C:\Users\HAJAR\Downloads\student-portfolio-source\routes.py", line 40, in register
    if form.validate_on_submit():
       ~~~~~~~~~~~~~~~~~~~~~~~^^
  File "C:\Users\HAJAR\AppData\Local\Programs\Python\Python313\Lib\site-packages\flask_wtf\form.py", line 86, in validate_on_submit
    return self.is_submitted() and self.validate(extra_validators=extra_validators)
                                   ~~~~~~~~~~~~~^^^^^^^^^^^^^^^^^^^^^^^^^^^^^^^^^^^
  File "C:\Users\HAJAR\AppData\Local\Programs\Python\Python313\Lib\site-packages\wtforms\form.py", line 330, in validate
    return super().validate(extra)
           ~~~~~~~~~~~~~~~~^^^^^^^
  File "C:\Users\HAJAR\AppData\Local\Programs\Python\Python313\Lib\site-packages\wtforms\form.py", line 147, in validate
    if not field.validate(self, extra):
           ~~~~~~~~~~~~~~^^^^^^^^^^^^^
  File "C:\Users\HAJAR\AppData\Local\Programs\Python\Python313\Lib\site-packages\wtforms\fields\core.py", line 234, in validate
    stop_validation = self._run_validation_chain(form, chain)
  File "C:\Users\HAJAR\AppData\Local\Programs\Python\Python313\Lib\site-packages\wtforms\fields\core.py", line 254, in _run_validation_chain
    validator(form, self)
    ~~~~~~~~~^^^^^^^^^^^^
  File "C:\Users\HAJAR\AppData\Local\Programs\Python\Python313\Lib\site-packages\wtforms\validators.py", line 403, in __call__
    raise Exception(
    ^^^^^^^^^^
Exception: Install 'email_validator' for email validation support.
INFO:werkzeug:127.0.0.1 - - [22/Apr/2025 16:38:45] "GET /register?__debugger__=yes&cmd=resource&f=style.css HTTP/1.1" 304 -
INFO:werkzeug:127.0.0.1 - - [22/Apr/2025 16:38:45] "GET /register?__debugger__=yes&cmd=resource&f=debugger.js HTTP/1.1" 304 -
INFO:werkzeug:127.0.0.1 - - [22/Apr/2025 16:38:45] "GET /register?__debugger__=yes&cmd=resource&f=console.png&s=ZE6QS26MonfmzHEm7qqx HTTP/1.1" 304 -
INFO:werkzeug:127.0.0.1 - - [22/Apr/2025 16:38:45] "GET /register?__debugger__=yes&cmd=resource&f=console.png HTTP/1.1" 304 -